2020-01-04 23:08:56,804 ERROR app.py line+6 <module> [MainThread]: Ups es un error generado :3
2020-01-04 23:11:08,896 ERROR capitulo9.py line+7 mensaje_bienvenida [MainThread]: Ups es un error generado :3
